package com.exceptionsmodule3;

public class Exception3 
{
public static void main(String[] args) 
{
System.out.println("main ethod started");
try
{
	int a=1/0;
System.out.println("joining");
System.out.println("demo");
System.out.println("first class");
System.out.println("testing");
System.out.println("java");
System.out.println("sql");
System.out.println("selenium");
System.out.println("aptitude");
}
catch(ArithmeticException ref)
{
	System.out.println("arithmatic exception");
}
finally
{
System.out.println("attending interview");
System.out.println("clear all rounds");
System.out.println("Happy Independence");
}
System.out.println("main method ended");
}
}
